Workbook

Sheet evSCAs
D1: IFA smears --> | H1: IFA smear counts (reader 1)--> | O1: Median of "Mean SCR" in all HbAA | P1: Fold change (FC) HbAC or HbAS relative to "Median SCR" in all HbAA | S1: IFA smear counts (reader 2; QC 12,5%) --> | X1: Cultures | Y1: Patient data | AE1: Parasite diagnosis and parasitemia
A2: ID | B2: Experiment (= Sample collection Number) | C2: Sample collection date | D2: IFA smear incl. CTRL | E2: IFA Replicate Number | F2: Sample | G2: Date of IFA staining | H2: Date of IFA counting | I2: Total_parasite_counts | J2: Gametocyte_counts | K2: Number fields counted | L2: Gametocyte stage V seen & not counted | M2: SCR | N2: Mean SCR | O2: Median SCR_HbAA | P2: FC SCR | Q2: Gametocytes_stageI_D1 | R2: Asexual_stages_D1 | S2: Number DAPI+ parasites | T2: Number of Pfs16+ sexual stages | U2: Number fields counted | V2: SCR | W2: Mean SCR | X2: Choline | Y2: HBB Genotype | Z2: Age | AA2: Gender | AB2: Village | AC2: Ethnicity | AD2: Symptomatic | AE2: RDT_D0 | AF2: LM_D0 | AG2: LM_par_µL_D0 | AH2: LM_par_percentage_D0 | AI2: LM_Gam_per_µl_D0 | AJ2: varATS_par_µL_D0 | AK2: varATS_par_percentage_D0 | AL2: MixInf
A3: 1 | B3: 1 | C3: 44783 | D3: YES | E3: 1 | F3: 1 | G3: 44784 | H3: 44852 | I3: 1023 | J3: 40 | K3: 28 | M3: 3.9100684 | N3: 3.7880746 | O3: =MEDIAN(N3,N9,N21,N24,N33,N42,N45,N48,N51,N57,N72,N81,N84,N87) -> 2.6753102 | Q3: =((J3)+(J4)+(J5))/((I3)+(I4)+(I5))*100 -> 3.8187702 | R3: =100-(Q3) -> 96.18123 | S3: 1101 | T3: 52 | V3: 4.7229791 | W3: =GEOMEAN(V3:V5) -> 4.537899 | X3: 0 | Y3: 0 | Z3: 6 | AA3: 0 | AB3: 1 | AC3: 1 | AD3: 1 | AE3: 1 | AF3: 1 | AG3: 1839 | AH3: 0.06 | AI3: 0 | AJ3: 6490 | AK3: 0.0198 | AL3: 0
C4: 44783 | E4: 2 | F4: 1 | G4: 44784 | H4: 44852 | I4: 1034 | J4: 33 | K4: 23 | M4: 3.1914894 | S4: 789 | T4: 38 | V4: 4.8162231 | Y4: 0 | AJ4: 6490
C5: 44783 | E5: 3 | F5: 1 | G5: 44784 | H5: 44852 | I5: 1033 | J5: 45 | K5: 30 | M5: 4.3562439 | S5: 925 | T5: 38 | V5: 4.1081081 | Y5: 0 | AJ5: 6490
A6: 2 | B6: 11 | C6: 44812 | D6: NO | E6: 1 | F6: 2 | G6: 44813 | H6: 24-25/11/2022 | I6: 1030 | J6: 49 | K6: 16 | L6: YES | M6: 4.7572816 | N6: 3.9595771 | P6: =(N6)/($O$3) -> 1.4800441 | Q6: =((J6)+(J7)+(J8))/((I6)+(I7)+(I8))*100 -> 4.0325203 | R6: =100-(Q6) -> 95.96748 | X6: 0 | Y6: 1 | Z6: 9.6 | AA6: 1 | AB6: 1 | AC6: 1 | AD6: 1 | AE6: 1 | AF6: 1 | AG6: 1690 | AH6: 0.05 | AI6: 0 | AJ6: 3350 | AK6: 0.067 | AL6: 0
C7: 44812 | E7: 2 | F7: 2 | G7: 44813 | H7: 24-25/11/2022 | I7: 1038 | J7: 31 | K7: 18 | L7: YES | M7: 2.9865125 | Y7: 1 | AJ7: 3350
C8: 44812 | E8: 3 | F8: 2 | G8: 44813 | H8: 24-25/11/2022 | I8: 1007 | J8: 44 | K8: 13 | L8: YES | M8: 4.3694141 | Y8: 1 | AJ8: 3350
A9: 3 | B9: 7 | C9: 44798 | D9: YES | E9: 1 | F9: 3 | G9: 44799 | H9: 44862 | I9: 1039 | J9: 17 | K9: 14 | M9: 1.6361886 | N9: 1.4669715 | Q9: =((J9)+(J10)+(J11))/((I9)+(I10)+(I11))*100 -> 1.5433071 | R9: =100-(Q9) -> 98.456693 | X9: 0 | Y9: 0 | Z9: 7.4 | AA9: 1 | AB9: 1 | AC9: 1 | AD9: 0 | AE9: 1 | AF9: 1 | AG9: 5333 | AH9: 0.1 | AI9: 0 | AJ9: 5333 | AK9: 0.00666 | AL9: 0
C10: 44798 | E10: 2 | F10: 3 | G10: 44799 | H10: 44862 | I10: 1088 | J10: 22 | K10: 19 | M10: 2.0220588 | Y10: 0 | AJ10: 5333
C11: 44798 | E11: 3 | F11: 3 | G11: 44799 | H11: 44862 | I11: 1048 | J11: 10 | K11: 14 | M11: 0.95419847 | Y11: 0 | AJ11: 5333
A12: 4 | B12: 1 | C12: 44783 | D12: YES | E12: 1 | F12: 4 | G12: 44784 | H12: 18-19/10/2022 | I12: 1021 | J12: 54 | K12: 40 | M12: 5.2889324 | N12: 3.5678 | P12: =(N12)/($O$3) -> 1.3336024 | Q12: =((J12)+(J13)+(J14))/((I12)+(I13)+(I14))*100 -> 3.8385827 | R12: =100-(Q12) -> 96.161417 | X12: 0 | Y12: 2 | Z12: 7.3 | AA12: 1 | AB12: 1 | AC12: 1 | AD12: 0 | AE12: 1 | AF12: 1 | AG12: 80 | AH12: 0.1 | AI12: 0 | AJ12: 6900 | AK12: 0.038 | AL12: 0
C13: 44783 | E13: 2 | F13: 4 | G13: 44784 | H13: 18-19/10/2022 | I13: 1008 | J13: 21 | K13: 25 | M13: 2.0833333 | Y13: 2 | AJ13: 6900
C14: 44783 | E14: 3 | F14: 4 | G14: 44784 | H14: 18-19/10/2022 | I14: 1019 | J14: 42 | K14: 29 | M14: 4.1216879 | Y14: 2 | AJ14: 6900
A15: 5 | B15: 2 | C15: 44784 | D15: YES | E15: 1 | F15: 5 | G15: 44785 | H15: 44851 | I15: 1000 | J15: 54 | K15: 20 | M15: 5.4 | N15: 5.1822911 | P15: =(N15)/($O$3) -> 1.9370804 | Q15: =((J15)+(J16)+(J17))/((I15)+(I16)+(I17))*100 -> 5.1849406 | R15: =100-(Q15) -> 94.815059 | S15: 996 | T15: 34 | V15: 3.4136546 | W15: =GEOMEAN(V15:V17) -> 2.6341806 | X15: 0 | Y15: 1 | Z15: 7.4 | AA15: 0 | AB15: 1 | AC15: 1 | AD15: 0 | AE15: 1 | AF15: 1 | AG15: 1966 | AH15: 0.06 | AI15: 0 | AJ15: 1110 | AK15: 0.0444 | AL15: 0
C16: 44784 | E16: 2 | F16: 5 | G16: 44785 | H16: 44851 | I16: 1016 | J16: 53 | K16: 31 | M16: 5.2165354 | S16: 1059 | T16: 29 | V16: 2.7384325 | Y16: 1 | AJ16: 1110
C17: 44784 | E17: 3 | F17: 5 | G17: 44785 | H17: 44851 | I17: 1012 | J17: 50 | K17: 26 | M17: 4.9407115 | S17: 716 | T17: 14 | V17: 1.9553073 | Y17: 1 | AJ17: 1110
A18: 6 | B18: 5 | C18: 44792 | D18: YES | E18: 1 | F18: 6 | G18: 44793 | H18: 09-10-25/01/2023 + 01/02/2023 | I18: 1012 | J18: 188 | K18: 58 | L18: YES | M18: 18.577075 | N18: 33.163404 | P18: =(N18)/($O$3) -> 12.396097 | Q18: =((J18)+(J19)+(J20))/((I18)+(I19)+(I20))*100 -> 37.252312 | R18: =100-(Q18) -> 62.747688 | X18: 0 | Y18: 2 | Z18: 8.5 | AA18: 1 | AB18: 1 | AC18: 1 | AD18: 1 | AE18: 1 | AF18: 1 | AG18: 40310 | AH18: 0.8 | AI18: 0 | AJ18: 87894 | AK18: 0.75788 | AL18: 0
C19: 44792 | E19: 2 | F19: 6 | G19: 44793 | H19: 09-10-25/01/2023 + 01/02/2023 | I19: 1009 | J19: 330 | K19: 90 | L19: YES | M19: 32.705649 | Y19: 2 | AJ19: 87894
C20: 44792 | E20: 3 | F20: 6 | G20: 44793 | H20: 09-10-25/01/2023 + 01/02/2023 | I20: 1007 | J20: 610 | K20: 105 | L20: YES | M20: 60.575968 | Y20: 2 | AJ20: 87894
A21: 7 | B21: 16 | C21: 44830 | D21: NO | E21: 1 | F21: 7 | G21: 44831 | H21: 44915 | I21: 1008 | J21: 52 | K21: 25 | M21: 5.1587302 | N21: 4.3407191 | Q21: =((J21)+(J22)+(J23))/((I21)+(I22)+(I23))*100 -> 4.3574361 | R21: =100-(Q21) -> 95.642564 | X21: 0 | Y21: 0 | Z21: 10.7 | AA21: 1 | AB21: 2 | AC21: 1 | AD21: 0 | AE21: 1 | AF21: 1 | AG21: 7333 | AH21: 0.1 | AI21: 0 | AJ21: 7334 | AK21: 0.34668 | AL21: 0
C22: 44830 | E22: 2 | F22: 7 | G22: 44831 | H22: 44915 | I22: 1057 | J22: 44 | K22: 22 | M22: 4.1627247 | Y22: 0 | AJ22: 7334
C23: 44830 | E23: 3 | F23: 7 | G23: 44831 | H23: 44915 | I23: 1102 | J23: 42 | K23: 24 | M23: 3.8112523 | Y23: 0 | AJ23: 7334
A24: 8 | B24: 16 | C24: 44830 | D24: NO | E24: 1 | F24: 8 | G24: 44831 | H24: 44931 | I24: 1031 | J24: 12 | K24: 12 | L24: YES | M24: 1.1639185 | N24: 1.2159671 | Q24: =((J24)+(J25)+(J26))/((I24)+(I25)+(I26))*100 -> 1.2191209 | R24: =100-(Q24) -> 98.780879 | X24: 0 | Y24: 0 | Z24: 6 | AA24: 1 | AB24: 2 | AC24: 1 | AD24: 1 | AE24: 1 | AF24: 1 | AG24: 3098 | AH24: 0.3 | AI24: 0 | AJ24: 55043 | AK24: 0.00186 | AL24: 0
C25: 44830 | E25: 2 | F25: 8 | G25: 44831 | H25: 44931 | I25: 1027 | J25: 12 | K25: 15 | L25: YES | M25: 1.1684518 | Y25: 0 | AJ25: 55043
C26: 44830 | E26: 3 | F26: 8 | G26: 44831 | H26: 44931 | I26: 1059 | J26: 14 | K26: 10 | L26: YES | M26: 1.3220019 | Y26: 0 | AJ26: 55043
A27: 9 | B27: 8 | C27: 44802 | D27: NO | E27: 1 | F27: 9 | G27: 44803 | H27: 27/10/2022 + 02-07-08-09-13-15-16-17-21-28/02/2023+ 01/03/2023 | I27: 1000 | J27: 259 | K27: 376 | L27: YES | M27: 25.9 | N27: 20.211266 | P27: =(N27)/($O$3) -> 7.5547373 | Q27: =((J27)+(J28)+(J29))/((I27)+(I28)+(I29))*100 -> 20.552965 | R27: =100-(Q27) -> 79.447035 | X27: 0 | Y27: 2 | Z27: 7.3 | AA27: 0 | AB27: 2 | AC27: 1 | AD27: 1 | AE27: 1 | AF27: 1 | AG27: 3037 | AH27: 0.06 | AI27: 78 | AJ27: 3931 | AK27: 0.07864 | AL27: 0
C28: 44802 | E28: 2 | F28: 9 | G28: 44803 | H28: 27/10/2022 + 02-07-08-09-13-15-16-17-21-28/02/2023+ 01/03/2023 | I28: 1000 | J28: 169 | K28: 241 | L28: YES | M28: 16.9 | Y28: 2 | AJ28: 3931
C29: 44802 | E29: 3 | F29: 9 | G29: 44803 | H29: 27/10/2022 + 02-07-08-09-13-15-16-17-21-28/02/2023+ 01/03/2023 | I29: 1002 | J29: 189 | K29: 217 | L29: YES | M29: 18.862275 | Y29: 2 | AJ29: 3931
A30: 10 | B30: 9 | C30: 44806 | D30: NO | E30: 1 | F30: 10 | G30: 44806 | H30: 44865 | I30: 1021 | J30: 11 | K30: 15 | M30: 1.0773751 | N30: 1.2351636 | Q30: =((J30)+(J31)+(J32))/((I30)+(I31)+(I32))*100 -> 1.2459016 | R30: =100-(Q30) -> 98.754098 | X30: 0 | Y30: 1 | Z30: 10.4 | AA30: 1 | AB30: 2 | AC30: 1 | AD30: 1 | AE30: 1 | AF30: 1 | AG30: 6190 | AH30: 0.03 | AI30: 0 | AJ30: 3105 | AK30: 0.164 | AL30: 0
C31: 44806 | E31: 2 | F31: 10 | G31: 44806 | H31: 44865 | I31: 1024 | J31: 12 | K31: 18 | M31: 1.171875 | Y31: 1 | AJ31: 3105
C32: 44806 | E32: 3 | F32: 10 | G32: 44806 | H32: 44865 | I32: 1005 | J32: 15 | K32: 15 | M32: 1.4925373 | Y32: 1 | AJ32: 3105
A33: 11 | B33: 16 | C33: 44830 | D33: NO | E33: 1 | F33: 11 | G33: 44831 | H33: 03-05/01/2023 | I33: 1015 | J33: 36 | K33: 71 | L33: YES | M33: 3.546798 | N33: 2.9017239 | Q33: =((J33)+(J34)+(J35))/((I33)+(I34)+(I35))*100 -> 2.979146 | R33: =100-(Q33) -> 97.020854 | X33: 0 | Y33: 0 | Z33: 4.9 | AA33: 0 | AB33: 2 | AC33: 1 | AD33: 1 | AE33: 1 | AF33: 1 | AG33: 1450 | AH33: 0.05 | AI33: 0 | AJ33: 4034 | AK33: 0.08068 | AL33: 0
C34: 44830 | E34: 2 | F34: 11 | G34: 44831 | H34: 03-05/01/2023 | I34: 1002 | J34: 33 | K34: 77 | L34: YES | M34: 3.2934132 | Y34: 0 | AJ34: 4034
C35: 44830 | E35: 3 | F35: 11 | G35: 44831 | H35: 03-05/01/2023 | I35: 1004 | J35: 21 | K35: 89 | L35: YES | M35: 2.0916335 | Y35: 0 | AJ35: 4034
A36: 12 | B36: 9 | C36: 44806 | D36: NO | E36: 1 | F36: 12 | G36: 44806 | H36: 44603 | I36: 1041 | J36: 81 | K36: 13 | M36: 7.7809798 | N36: 7.0124746 | P36: =(N36)/($O$3) -> 2.6211818 | Q36: =((J36)+(J37)+(J38))/((I36)+(I37)+(I38))*100 -> 7.0490227 | R36: =100-(Q36) -> 92.950977 | X36: 0 | Y36: 1 | Z36: 8 | AA36: 0 | AB36: 2 | AC36: 1 | AD36: 1 | AE36: 1 | AF36: 1 | AG36: 7630 | AH36: 0.4 | AI36: 0 | AJ36: 10360 | AK36: 0.40711 | AL36: 0
C37: 44806 | E37: 2 | F37: 12 | G37: 44806 | H37: 44603 | I37: 1005 | J37: 76 | K37: 16 | M37: 7.5621891 | Y37: 1 | AJ37: 10360
C38: 44806 | E38: 3 | F38: 12 | G38: 44806 | H38: 44603 | I38: 1075 | J38: 63 | K38: 9 | M38: 5.8604651 | Y38: 1 | AJ38: 10360
A39: 13 | B39: 10 | C39: 44809 | D39: NO | E39: 1 | F39: 13 | G39: 44807 | H39: 44869 | I39: 1016 | J39: 65 | K39: 13 | M39: 6.3976378 | N39: 7.7787663 | P39: =(N39)/($O$3) -> 2.9076128 | Q39: =((J39)+(J40)+(J41))/((I39)+(I40)+(I41))*100 -> 7.8596947 | R39: =100-(Q39) -> 92.140305 | X39: 0 | Y39: 1 | Z39: 7.8 | AA39: 1 | AB39: 2 | AC39: 1 | AD39: 1 | AE39: 1 | AF39: 1 | AG39: 4538 | AH39: 0.3 | AI39: 0 | AJ39: 18838 | AK39: 0.57676 | AL39: 0
C40: 44809 | E40: 2 | F40: 13 | G40: 44807 | H40: 44869 | I40: 1015 | J40: 86 | K40: 20 | M40: 8.4729064 | Y40: 1 | AJ40: 18838
...

Sheet evSCAs - Data dictionary
A1: ITEM_NAME | B1: DESCRIPTION_LABEL | C1: RESPONSE_LABEL | D1: RESPONSE_OPTIONS_TEXT | E1: DATA_TYPE | F1: COMMENTS
A2: ID | B2: Sample number | E2: Character String (ST)
A3: Experiment (= Sample collection Number) | B3: Experiment in which samples are included, this is done by sample collection | C3: Experiment | D3: 1 to 16 | E3: Categorical (CAT)
A4: Sample collection date | B4: Date when the sample was collected | C4: Sample collection date | E4: Temporal (Ordinal)
A5: IFA smear incl. CTRL | B5: Did the IFA smear include a negative control without primary antibody anti-Pfs16? | C5: IFA smear incl. CTRL | D5: YES, NO | E5: Categorical (CAT)
A6: IFA Replicate Number | B6: Number of IFA smear replicates from one same blood sample and parasite culture | C6: IFA Replicate nr. | E6: Continuous (CONT)
A7: Sample | B7: Cultured P. falciparum sample, three triplicates per culture (sample/culture number "1" = three replicates with each as number "1") | C7: Sample | D7: Sample | E7: INT
A8: Date of IFA staining | B8: Date when IFA smear was stained for IFA | C8: Date of IFA staining | E8: Temporal (Ordinal)
A9: Date o IFA counting | B9: Date when IFA smear was counted for IFA | C9: Date of IFA counting | E9: Temporal (Ordinal) | F9: Reader 1
A10: Total_parasite_counts | B10: Number of parasites coloured with DAPI DNA stain | C10: Number DAPI+ parasites | E10: Continuous (CONT) | F10: Reader 1 + Reader 2
A11: Gametocyte_counts | B11: Number of Pfs16+ gametocytes stage I | C11: Number of Pfs16+ sexual stages | E11: Continuous (CONT) | F11: Reader 1 + Reader 2
A12: Number fields counted | B12: Number of fields needed to be counted to reach at least 1000 DAPI+ parasites | C12: Number fields counted | E12: Continuous (CONT) | F12: Reader 1 + Reader 2
A13: Gametocyte stage V seen & not counted | B13: Were gametocytes stage V present in the IFA smear and were excluded from the "Number of Pfs16+ sexual stages"? | C13: Gametocyte stage V seen & not counted | D13: YES, NO | E13: Categorical (CAT) | F13: Reader 1
A14: SCR | B14: Per IFA replicate: Proportion of sexual parasites on the total parasitemia i.e. ("Number of Pfs16+ sexual stages")/("Number of DAPI/ parasites")*100 | C14: SCR | E14: Continuous (CONT) | F14: Reader 1 + Reader 2
A15: Mean SCR | B15: Mean of the SCR of the three IFA replicates per sample | C15: Mean SCR | E15: Continuous (CONT) | F15: Reader 1 + Reader 2
A16: Median SCR_HbAA | B16: Median of "Mean SCR" in all HbAA samples | C16: Median SCR_HbAA | E16: Continuous (CONT) | F16: Reader 1 (main)
A17: FC SCR | B17: Fold change (FC) in HbXX (with XX = AC or AS) relative to "Median SCR" of all HbAA samples i.e., SCR in HbXX (with XX = AC or AS) divided by SCR in HbAA | C17: FC SCR | E17: Continuous (CONT) | F17: Reader 1 (main)
A18: Gametocytes_stageI_D1 | B18: Proportion of sexual Pfs16+ parasites on the total counted parasites (DAPI+) by IFA after MACS at Day 1 (D1) | C18: Mean_proportion Sexual par_Pfs16+_D1 | E18: Continuous (CONT) | F18: Reader 1 (main)
A19: Asexual_stages_D1 | B19: Proportion of Asexual parasites on the total counted parasites (DAPI+) by IFA after MACS at Day 1 (D1) | C19: Mean_proportion Asexual par_D1 | E19: Continuous (CONT) | F19: Reader 1 (main)
A20: Choline | B20: Choline+ or Choline- culture medium used? | C20: Choline + or Choline- | D20: (+) = 1; (-) = 0 | E20: Categorical (CAT)
A21: HBB Genotype | B21: Hemoglobin beta (HBB) genotype | C21: HBB Genotype | D21: HbAA = 0; HbAC = 1; HbAS = 2 | E21: Categorical (CAT)
A22: Age | B22: Age, months expressed in years | C22: Age | E22: Continuous (CONT)
A23: Gender | B23: Gender | C23: Codified variable | D23: Codified variable | E23: Categorical (CAT)
A24: Village | B24: Village | C24: Codified variable | D24: Codified variable | E24: Categorical (CAT)
A25: Ethnicity | B25: Ethnicity | C25: Codified variable | D25: Codified variable | E25: Categorical (CAT)
A26: Symptomatic | B26: Did the participant have symptoms at the time of sample collection? | C26: Codified variable | D26: Codified variable | E26: Categorical (CAT)
A27: RDT_D0 | B27: What is the result of the RDT at the time of saple collection? | C27: RDT result | D27: Positive = 1, Negative = 0 | E27: Categorical (CAT)
A28: LM_D0 | B28: What is the result of the Light microscopy diagnosis at the time of sample collection (Day 0 i.e., D0)? | C28: LM result | D28: Positive = 1, Negative = 0 | E28: Categorical (CAT)
A29: LM_par_µL_D0 | B29: Light microscopy parasite counts per µL, at the time of sample collection (Day 0 i.e., D0) | C29: LM par/µL | E29: Continuous (CONT)
A30: LM_par_percentage_D0 | B30: Light microscopy parasite counts as % on total counted red blood cells, at the time of sample collection (Day 0 i.e., D0) | C30: LM par% | E30: Continuous (CONT)
A31: LM_Gam_per_µl_D0 | B31: Light microscopy gametocyte counts per µL, at the time of sample collection (Day 0 i.e., D0) | C31: LM Gam/µL | E31: Continuous (CONT)
A32: varATS_par_µL_D0 | B32: varATS qPCR results as parasites per µL, at the time of sample collection (Day 0 i.e., D0) | C32: varATS par/µL | E32: Continuous (CONT)
A33: varATS_par_percentage_D0 | B33: varATS qPCR results as parasites %, at the time of sample collection (Day 0 i.e., D0) | C33: varATS par% | E33: Continuous (CONT)
A34: MixInf | B34: Where there mixed Plasmodium species where seen during light licroscopy evaluation? | C34: MixInf | D34: No = 0, Yes =1 | E34: Categorical (CAT)

Sheet ivSCAs
F1: Patient data --> | L1: Parasite cultures - Flow Cytometry Data --> | BB1: BX to CQ columns: GLMM analysis (proportion on counts) --> | BV1: Parasite cultures - Light Microscopy (LM) Data -->
N2: Number of RBC events / Sample Volume | Q2: Number of RBC events / Sample Volume | T2: Number of RBC events / Sample Volume | AD2: iRBCs% post-sorbitol before SC, Must be <=2,0% | AI2: Asexual and sexual iRBCs% at Generation 1, 25-30 hpi (+CHOLINE cultures) | AK2: Asexual and sexual iRBCs% at Generation 1, 35-40 hpi (+CHOLINE cultures) | AQ2: Median of SCR in all HbAA "TEST" samples | AR2: Fold-change of AC, AS, SC and SS "TEST" samples, relative to "Median SCR" in all HbAA "TEST" samples | AV2: Asexual and sexual iRBCs% at Generation1, 25-30 hpi (-CHOLINE cultures) | AX2: Asexual and sexual iRBCs% at Generation 1, 35-40 hpi (-CHOLINE cultures) | BB2: BX and BY columns: Initial parasitemia counts at 0-5hpi | BD2: BZ and CA columns: +Choline cultures at Gen0 35-40hpi: Late stages proportion | BF2: CB to CE columns: +Choline cultures at Gen1 25-30hpi, Sexual conversion data (CB, CC and CD) and Late stages proportion data (CB and CE) | BJ2: CF to CI columns: +Choline cultures at Gen1 35-40hpi, Sexual conversion data (CF, CG and CI) and Late stages proportion data (CF and CI) | BN2: CJ to CL columns: -Choline cultures at Gen1 25-30hpi, Sexual conversion data | BQ2: CM to CO columns: -Choline cultures at Gen1 35-40hpi, Sexual conversion data | BT2: CP to CQ: Reticulocytes proportion data (CP/CQ)*100
A3: ID | B3: Group | C3: Sample type | D3: Experiment Number | E3: Date start experiment | F3: HBB Genotype | G3: Bloodgroup | H3: Reticulocytes | I3: Gender | J3: CollectionSite | K3: Symptomatic | L3: Number RBC events_CHOLINE_Gen0_35to40hpi | M3: Sample volume_CHOLINE_Gen0_35to40hpi | N3: RBCs_per_µL _CHOLINE_Gen0_35to40hpi | O3: Number RBC events_CHOLINE_Gen1_25to30hpi | P3: Sample volume_CHOLINE_Gen1_25to30hpi | Q3: RBCs_per_µl_CHOLINE_Gen1_25to30hpi | R3: Number RBC events_CHOLINE_Gen1_35to40hpi | S3: Sample volume_CHOLINE_Gen1_35to40hpi | T3: RBCs_per_µL _CHOLINE_Gen1_35to40hpi | U3: PMR_CHOLINE_Gen0_1 | V3: DNAcontent_CHOLINE_Gen0_35to40hpi | W3: DNAcontent_CHOLINE_Gen1_35to40hpi | X3: LateStages_CHOLINE_Gen0_35to40hpi | Y3: LateStages_CHOLINE_Gen1_25to30hpi | Z3: LateStages_CHOLINE_Gen1_35to40hpi | AA3: LateStages_Proportion_CHOLINE_Gen0_35to40hpi | AB3: LateStages_Proportion_CHOLINE_Gen1_25to30hpi | AC3: LateStagesProportion_CHOLINE_Gen1_35to40hpi | AD3: iRBCs_Gen0_0to5hpi | AE3: iRBCs_CHOLINE_Gen0_35to40hpi | AF3: iRBCs_CHOLINE_Gen1_25to30hpi | AG3: iRBCs_CHOLINE_Gen1_35to40hpi | AH3: Raw iRBC counts_CHOLINE_Gen1_35to40hpi | AI3: Sexual_iRBCs_CHOLINE_Gen1_25to30hpi | AJ3: Asexual_iRBCs_CHOLINE_Gen1_25to30hpi | AK3: Sexual_iRBCs_CHOLINE_Gen1_35to40hpi | AL3: Asexual_iRBCs_CHOLINE_Gen1_35to40hpi | AM3: Raw Sexual iRBCs counts_CHOLINE_Gen1_35to40hpi | AN3: Raw Asexual iRBCs counts_CHOLINE_Gen1_35to40hpi | AO3: SCR_CHOLINE_Gen1_25to30hpi | AP3: SCR_CHOLINE_Gen1_35to40hpi | AQ3: Median SCR_HbAA | AR3: FC_SCR_CHOLINE_Gen1_35to40hpi | AS3: iRBCs_NO_CHOLINE_Gen0_35to40hpi | AT3: iRBCs_NO_CHOLINE_Gen1_25to30hpi | AU3: iRBCs_NO_CHOLINE_Gen1_35to40hpi | AV3: Sexual_iRBCs_NoCHOLINE_Gen1_25to30hpi | AW3: Asexual_iRBCs_NO_CHOLINE_Gen1_25to30hpi | AX3: Sexual_iRBCs_NO_CHOLINE_Gen1_35to40hpi | AY3: Asexual_iRBCs_NO_CHOLINE_Gen1_35to40hpi | AZ3: SCR_NO_CHOLINE_Gen1_25to30hpi | BA3: SCR_NO_CHOLINE_Gen1_35to40hpi | BB3: Raw counts_RBC_CHOLINE_Gen0_0to5hpi | BC3: Raw counts_iRBCs_CHOLINE_Gen0_0to5hpi | BD3: Raw counts_iRBCs_CHOLINE_Gen0_35to40hpi | BE3: Raw counts_Late stages_CHOLINE_Gen0_35to40hpi | BF3: Raw counts_iRBCs_CHOLINE_Gen1_25to30hpi | BG3: Raw counts_Asexual iRBCs_CHOLINE_Gen1_25to30hpi | BH3: Raw counts_Sexual iRBCs_CHOLINE_Gen1_25to30hpi | BI3: Raw counts_Late stages_CHOLINE_Gen1_25to30hpi | BJ3: Raw counts_iRBCs_CHOLINE_Gen1_35to40hpi | BK3: Raw counts_Asexual iRBCs_CHOLINE_Gen1_35to40hpi | BL3: Raw counts_Sexual iRBCs_CHOLINE_Gen1_35to40hpi | BM3: Raw counts_Late stages_CHOLINE_Gen1_35to40hpi | BN3: Raw counts_iRBCs_NO CHOLINE_Gen1_25to30hpi | BO3: Raw counts_Asexual iRBCs_NO CHOLINE_Gen1_25to30hpi | BP3: Raw counts_Sexual iRBCs_NO CHOLINE_Gen1_25to30hpi | BQ3: Raw counts_iRBCs_NO CHOLINE_Gen1_35to40hpi | BR3: Raw counts_Asexual iRBCs_NO CHOLINE_Gen1_35to40hpi | BS3: Raw counts_Sexual iRBCs_NO CHOLINE_Gen1_35to40hpi | BT3: Raw counts_Retics_Reticulocytes | BU3: Raw counts_Retics_total RBCs | BV3: LM_total_iRBCs_counts_CHOLINE_Gen0_35to40hpi | BW3: LM_total_iRBCs_counts_CHOLINE_Gen1_25to30hpi | BX3: LM_total_iRBCs_counts_CHOLINE_Gen1_35to40hpi | BY3: TinyRings_Proportion_CHOLINE_Gen0_35to40hpi | BZ3: TinyRings_Proportion_CHOLINE_Gen1_25to30hpi | CA3: TinyRings_Proportion_CHOLINE_Gen1_35to40hpi | CB3: SmallRings_Proportion_CHOLINE_Gen0_35to40hpi | CC3: SmallRings_Proportion_CHOLINE_Gen1_25to30hpi | CD3: SmallRings_Proportion_CHOLINE_Gen1_35to40hpi | CE3: LargeRings_Proportion_CHOLINE_Gen0_35to40hpi | CF3: LargeRings_Proportion_CHOLINE_Gen1_25to30hpi | CG3: LargeRings_Proportion_CHOLINE_Gen1_35to40hpi | CH3: EarlyTrophs_Proportion_CHOLINE_Gen0_35to40hpi | CI3: EarlyTrophs_Proportion_CHOLINE_Gen1_25to30hpi | CJ3: EarlyTrophs_Proportion_CHOLINE_Gen1_35to40hpi | CK3: MidTrophs_Proportion_CHOLINE_Gen0_35to40hpi | CL3: MidTrophs_Proportion_CHOLINE_Gen1_25to30hpi | CM3: MidTrophs_Proportion_CHOLINE_Gen1_35to40hpi | CN3: LateTrophs_Proportion_CHOLINE_Gen0_35to40hpi | CO3: LateTrophs_Proportion_CHOLINE_Gen1_25to30hpi | CP3: LateTrophs_Proportion_CHOLINE_Gen1_35to40hpi | CQ3: EarlySchizonts_Proportion_CHOLINE_Gen0_35to40hpi | CR3: EarlySchizonts_Proportion_CHOLINE_Gen1_25to30hpi | CS3: EarlySchizonts_Proportion_CHOLINE_Gen1_35to40hpi | CT3: LateSchizonts_Proportion_CHOLINE_Gen0_35to40hpi | CU3: LateSchizonts_Proportion_CHOLINE_Gen1_25to30hpi | CV3: LateSchizonts_Proportion_CHOLINE_Gen1_35to40hpi
A4: 1 | B4: AA CTRL | C4: CTRL FRESH | D4: 1 | E4: 45607 | F4: 0 | G4: 0 | H4: 0.46 | I4: 1 | J4: 2 | K4: 0 | L4: 100000 | M4: 3.5 | N4: =(L4)/(M4) -> 28571.429 | O4: 100000 | P4: 2.9 | Q4: =(O4)/(P4) -> 34482.759 | R4: 100000 | S4: 3.1 | T4: =(R4)/(S4) -> 32258.065 | U4: 3.1111111 | V4: 55581.63 | W4: 31406.7 | X4: 0.81 | Y4: 0.43 | Z4: 1.41 | AA4: 60 | AB4: 10.046729 | AC4: 33.571429 | AD4: 0.82758621 | AE4: 1.35 | AF4: 4.28 | AG4: 4.2 | AH4: =(AG4/100)*100000 -> 4200 | AI4: 7.59 | AJ4: 92.3 | AK4: 8.78 | AL4: 90.85 | AM4: =(AK4/100)*(AH4) -> 368.76 | AN4: =(AL4/100)*(AH4) -> 3815.7 | AO4: 7.5983582 | AP4: 8.8126066 | AQ4: =MEDIAN(AP9,AP18:AP20,AP28) -> 10.782644 | AS4: 1.35 | AT4: 3.55 | AU4: 3.36 | AV4: 22.27 | AW4: 77.57 | AX4: 26.69 | AY4: 72.94 | AZ4: 22.305689 | BA4: 26.78912 | BB4: 1450 | BC4: 12 | BD4: 1202 | BE4: 717 | BF4: 3819 | BG4: 3525 | BH4: 290 | BI4: 380 | BJ4: 3782 | BK4: 3436 | BL4: 332 | BM4: 1270 | BN4: 3179 | BO4: 2466 | BP4: 708 | BQ4: 3001 | BR4: 2189 | BS4: 801 | BT4: 8 | BU4: 1753 | BV4: 127 | BW4: 100 | BX4: 103 | BZ4: 13 | CA4: 3.8834951 | CF4: 31 | CJ4: 1.9417476 | CL4: 51 | CM4: 14.563107 | CN4: 12.598425 | CO4: 2 | CP4: 19.417476 | CQ4: 28.346457 | CR4: 2 | CS4: 46.601942 | CT4: 59.055118 | CU4: 1 | CV4: 13.592233
A5: 2 | B5: AS | C5: TEST | D5: 1 | E5: 45607 | F5: 2 | G5: 0 | H5: 1.78 | I5: 1 | J5: 0 | K5: 1 | L5: 100000 | M5: 7 | N5: =(L5)/(M5) -> 14285.714 | O5: 100000 | P5: 6.5 | Q5: =(O5)/(P5) -> 15384.615 | R5: 100000 | S5: 5.9 | T5: =(R5)/(S5) -> 16949.153 | U5: 2.454918 | V5: 32636.05 | W5: 12951.06 | X5: 0.98 | Y5: 0.33 | Z5: 0.87 | AA5: 40.163934 | AB5: 5.221519 | AC5: 14.524207 | AD5: 2 | AE5: 2.44 | AF5: 6.32 | AG5: 5.99 | AH5: =(AG5/100)*100000 -> 5990 | AI5: 25 | AJ5: 74.79 | AK5: 26.22 | AL5: 73.6 | AM5: =(AK5/100)*(AH5) -> 1570.578 | AN5: =(AL5/100)*(AH5) -> 4408.64 | AO5: 25.05261 | AP5: 26.267281 | AR5: =AP5/$AQ$4 -> 2.4360706 | AS5: 2.44 | AT5: 4.41 | AU5: 3.89 | AV5: 33.72 | AW5: 66.11 | AX5: 38.37 | AY5: 61.52 | AZ5: 33.777422 | BA5: 38.412253 | BB5: 950 | BC5: 8 | BD5: 2229 | BE5: 891 | BF5: 5760 | BG5: 4308 | BH5: 1440 | BI5: 301 | BJ5: 5473 | BK5: 4028 | BL5: 1435 | BM5: 795 | BN5: 3998 | BO5: 2643 | BP5: 1348 | BQ5: 3550 | BR5: 2184 | BS5: 1362 | BT5: 19 | BU5: 1065 | BV5: 111 | BW5: 107 | BX5: 125 | BY5: 6.3063063 | BZ5: 13.084112 | CA5: 12.8 | CE5: 9.9099099 | CF5: 56.074766 | CG5: 7.2 | CH5: 13.513514 | CI5: 3.7383178 | CJ5: 15.2 | CK5: 0.9009009 | CL5: 22.429907 | CM5: 33.6 | CN5: 24.324324 | CO5: 4.6728972 | CP5: 12.8 | CQ5: 21.621622 | CS5: 16.8 | CT5: 23.423423 | CV5: 1.6
A6: 3 | B6: AS | C6: TEST | D6: 1 | E6: 45607 | F6: 2 | G6: 2 | H6: 1.65 | I6: 1 | J6: 0 | K6: 0 | L6: 100000 | M6: 5.1 | N6: =(L6)/(M6) -> 19607.843 | O6: 100000 | P6: 5.6 | Q6: =(O6)/(P6) -> 17857.143 | R6: 100000 | S6: 5.3 | T6: =(R6)/(S6) -> 18867.925 | U6: 2.6047619 | V6: 32628.93 | W6: 13404.66 | X6: 0.69 | Y6: 0.34 | Z6: 0.87 | AA6: 32.857143 | AB6: 5.9130435 | AC6: 15.904936 | AD6: 2 | AE6: 2.1 | AF6: 5.75 | AG6: 5.47 | AH6: =(AG6/100)*100000 -> 5470 | AI6: 17.17 | AJ6: 82.67 | AK6: 18.24 | AL6: 81.66 | AM6: =(AK6/100)*(AH6) -> 997.728 | AN6: =(AL6/100)*(AH6) -> 4466.802 | AO6: 17.197516 | AP6: 18.258258 | AR6: =AP6/$AQ$4 -> 1.6933007 | AS6: 2.1 | AT6: 4.03 | AU6: 3.9 | AV6: 31.19 | AW6: 68.72 | AX6: 31.89 | AY6: 67.91 | AZ6: 31.218096 | BA6: 31.953908 | BB6: 992.5 | BC6: 12 | BD6: 1865 | BE6: 613 | BF6: 5160 | BG6: 4266 | BH6: 886 | BI6: 302 | BJ6: 4956 | BK6: 4047 | BL6: 904 | BM6: 786 | BN6: 3600 | BO6: 2474 | BP6: 1123 | BQ6: 3512 | BR6: 2385 | BS6: 1120 | BT6: 13 | BU6: 788 | BV6: 104 | BW6: 104 | BX6: 100 | BY6: 15.384615 | BZ6: 9.6153846 | CA6: 20 | CF6: 43.269231 | CG6: 6 | CH6: 8.6538462 | CI6: 3.8461538 | CJ6: 17 | CL6: 43.269231 | CM6: 25 | CN6: 30.769231 | CP6: 7 | CQ6: 22.115385 | CS6: 20 | CT6: 23.076923 | CV6: 5
A7: 4 | B7: AC | C7: TEST | D7: 1 | E7: 45607 | F7: 1 | G7: 2 | H7: 1.35 | I7: 1 | J7: 0 | K7: 0 | L7: 100000 | M7: 7.6 | N7: =(L7)/(M7) -> 13157.895 | O7: 100000 | P7: 6.1 | Q7: =(O7)/(P7) -> 16393.443 | R7: 100000 | S7: 5.6 | T7: =(R7)/(S7) -> 17857.143 | U7: 1.8290155 | V7: 49786.25 | W7: 25577.33 | X7: 1.19 | Y7: 0.55 | Z7: 1 | AA7: 61.658031 | AB7: 12.443439 | AC7: 28.328612 | AD7: 1.209068 | AE7: 1.93 | AF7: 4.42 | AG7: 3.53 | AH7: =(AG7/100)*100000 -> 3530 | AI7: 8.5 | AJ7: 91.39 | AK7: 11.29 | AL7: 88.52 | AM7: =(AK7/100)*(AH7) -> 398.537 | AN7: =(AL7/100)*(AH7) -> 3124.756 | AO7: 8.5093603 | AP7: 11.311492 | AR7: =AP7/$AQ$4 -> 1.0490463 | AS7: 1.93 | AT7: 2.59 | AU7: 2.4 | AV7: 22.9 | AW7: 76.72 | AX7: 25.8 | AY7: 74.02 | AZ7: 22.987352 | BA7: 25.846524 | BB7: 887.5 | BC7: 20 | BD7: 1725 | BE7: 1065 | BF7: 3904 | BG7: 3568 | BH7: 332 | BI7: 482 | BJ7: 3198 | BK7: 2831 | BL7: 361 | BM7: 908 | BN7: 2328 | BO7: 1786 | BP7: 533 | BQ7: 2163 | BR7: 1601 | BS7: 558 | BT7: 13 | BU7: 965 | BV7: 105 | BW7: 104 | BX7: 111 | BY7: 3.8095238 | BZ7: 16.346154 | CA7: 9.009009 | CE7: 2.8571429 | CF7: 24.038462 | CG7: 0.9009009 | CH7: 0.95238095 | CL7: 55.769231 | CM7: 21.621622 | CN7: 14.285714 | CO7: 2.8846154 | CP7: 10.810811 | CQ7: 40 | CR7: 0.96153846 | CS7: 36.936937 | CT7: 38.095238 | CV7: 20.720721
A8: 5 | B8: AA CTRL | C8: CTRL FRESH | D8: 2 | E8: 45621 | F8: 0 | G8: 0 | H8: 0.35 | I8: 1 | J8: 2 | K8: 0 | L8: 100000 | M8: 6.8 | N8: =(L8)/(M8) -> 14705.882 | O8: 100000 | P8: 6.6 | Q8: =(O8)/(P8) -> 15151.515 | R8: 100000 | S8: 3.7 | T8: =(R8)/(S8) -> 27027.027 | U8: 4.6956522 | V8: 26603.88 | W8: 20262.73 | X8: 0.43 | Y8: 0.19 | Z8: 1.19 | AA8: 46.73913 | AB8: 7.6923077 | AC8: 25.265393 | AD8: 0.2 | AE8: 0.92 | AF8: 2.47 | AG8: 4.71 | AH8: =(AG8/100)*100000 -> 4710 | AI8: 10.46 | AJ8: 89.33 | AK8: 7.26 | AL8: 92.62 | AM8: =(AK8/100)*(AH8) -> 341.946 | AN8: =(AL8/100)*(AH8) -> 4362.402 | AO8: 10.482012 | AP8: 7.2687225 | AS8: 0.92 | AT8: 1.87 | AU8: 2.85 | AV8: 31.37 | AW8: 68.51 | AX8: 33.07 | AY8: 66.67 | AZ8: 31.407689 | BA8: 33.156206 | BB8: 92700 | BC8: 184 | BD8: 864 | BE8: 401 | BF8: 2324 | BG8: 2076 | BH8: 243 | BI8: 175 | BJ8: 4352 | BK8: 316 | BL8: 4031 | BM8: 1102 | BN8: 1769 | BO8: 1212 | BP8: 555 | BQ8: 2658 | BR8: 1772 | BS8: 879 | BT8: 4 | BU8: 1158
A9: 6 | B9: AA | C9: TEST | D9: 2 | E9: 45621 | F9: 0 | G9: 4 | H9: 1 | I9: 1 | J9: 0 | K9: 0 | L9: 100000 | M9: 10.1 | N9: =(L9)/(M9) -> 9900.9901 | O9: 100000 | P9: 9.7 | Q9: =(O9)/(P9) -> 10309.278 | R9: 100000 | S9: 5.4 | T9: =(R9)/(S9) -> 18518.519 | U9: 3.7977528 | V9: 29522.28 | W9: 27215.86 | X9: 0.47 | Y9: 0.19 | Z9: 1.33 | AA9: 52.808989 | AB9: 6.7857143 | AC9: 34.102564 | AD9: 0.16 | AE9: 0.89 | AF9: 2.8 | AG9: 3.9 | AH9: =(AG9/100)*100000 -> 3900 | AI9: 9.44 | AJ9: 90.56 | AK9: 10.9 | AL9: 88.81 | AM9: =(AK9/100)*(AH9) -> 425.1 | AN9: =(AL9/100)*(AH9) -> 3463.59 | AO9: 9.44 | AP9: 10.931702 | AS9: 0.89 | AT9: 1.88 | AU9: 3.24 | AV9: 23.49 | AW9: 76.33 | AX9: 29.02 | AY9: 70.8 | AZ9: 23.532358 | BA9: 29.07233 | BB9: 93494 | BC9: 144 | BD9: 797 | BE9: 425 | BF9: 2499 | BG9: 2263 | BH9: 236 | BI9: 167 | BJ9: 3413 | BK9: 372 | BL9: 3031 | BM9: 1164 | BN9: 1694 | BO9: 1293 | BP9: 398 | BQ9: 2860 | BR9: 2025 | BS9: 830 | BT9: 11 | BU9: 1098
A10: 7 | B10: AC | C10: TEST | D10: 2 | E10: 45621 | F10: 1 | G10: 4 | H10: 2.48 | I10: 1 | J10: 0 | K10: 1 | L10: 100000 | M10: 6.6 | N10: =(L10)/(M10) -> 15151.515 | O10: 100000 | P10: 6.9 | Q10: =(O10)/(P10) -> 14492.754 | R10: 100000 | S10: 4.4 | T10: =(R10)/(S10) -> 22727.273 | U10: 4.5571429 | V10: 27641.06 | W10: 22698.26 | X10: 0.36 | Y10: 0.1 | Z10: 1.13 | AA10: 51.428571 | AB10: 4.2918455 | AC10: 31.830986 | AD10: 0.13 | AE10: 0.7 | AF10: 2.33 | AG10: 3.55 | AH10: =(AG10/100)*100000 -> 3550 | AI10: 9.4 | AJ10: 90.51 | AK10: 10.38 | AL10: 89.22 | AM10: =(AK10/100)*(AH10) -> 368.49 | AN10: =(AL10/100)*(AH10) -> 3167.31 | AO10: 9.4084676 | AP10: 10.421687 | AR10: =AP10/$AQ$4 -> 0.96652428 | AS10: 0.7 | AT10: 1.8 | AU10: 2.75 | AV10: 28.52 | AW10: 71.36 | AX10: 2.75 | AY10: 33.05 | AZ10: 66.79 | BA10: 33.102965 | BB10: 95898 | BC10: 125 | BD10: 649 | BE10: 339 | BF10: 2149 | BG10: 1945 | BH10: 202 | BI10: 90 | BJ10: 3199 | BK10: 332 | BL10: 2854 | BM10: 1020 | BN10: 1669 | BO10: 1191 | BP10: 476 | BQ10: 2502 | BR10: 1671 | BS10: 827 | BT10: 17 | BU10: 685
A11: 8 | B11: AC | C11: TEST | D11: 2 | E11: 45621 | F11: 1 | G11: 0 | H11: 0.62 | I11: 0 | J11: 0 | K11: 0 | O11: 100000 | P11: 59.5 | Q11: =(O11)/(P11) -> 1680.6723 | R11: 100000 | S11: 30.9 | T11: =(R11)/(S11) -> 3236.246 | W11: 9354.72 | X11: 1.45 | Y11: 0.08 | Z11: 0.28 | AA11: 60.669456 | AB11: 3.7914692 | AC11: 8.7227414 | AD11: 0.44 | AE11: 2.39 | AF11: 2.11 | AG11: 3.21 | AH11: =(AG11/100)*100000 -> 3210 | AI11: 16.95 | AJ11: 82.86 | AK11: 15.91 | AL11: 83.42 | AM11: =(AK11/100)*(AH11) -> 510.711 | AN11: =(AL11/100)*(AH11) -> 2677.782 | AO11: 16.982266 | AP11: 16.017316 | AR11: =AP11/$AQ$4 -> 1.4854721 | AS11: 2.39 | AT11: 1.43 | AU11: 2.65 | AV11: 15.53 | AW11: 83.93 | AX11: 2.65 | AY11: 25.12 | AZ11: 74.21 | BA11: 25.289439 | BB11: 96224 | BC11: 402 | BF11: 1634 | BG11: 1354 | BH11: 277 | BI11: 62 | BJ11: 2364 | BK11: 376 | BL11: 1972 | BM11: 203 | BN11: 1095 | BO11: 919 | BP11: 170 | BQ11: 1931 | BR11: 1433 | BS11: 485 | BT11: 5 | BU11: 808
A12: 9 | B12: AS | C12: TEST | D12: 2 | E12: 45621 | F12: 2 | G12: 4 | H12: 2.8 | I12: 1 | J12: 0 | K12: 0 | L12: 100000 | M12: 5.6 | N12: =(L12)/(M12) -> 17857.143 | O12: 100000 | P12: 5.5 | Q12: =(O12)/(P12) -> 18181.818 | R12: 100000 | S12: 3.4 | T12: =(R12)/(S12) -> 29411.765 | U12: 4.4533333 | V12: 13213.77 | W12: 8511.18 | X12: 0.14 | Y12: 0.03 | Z12: 0.2 | AA12: 18.666667 | AB12: 1.7045455 | AC12: 5.1413882 | AD12: 0.15 | AE12: 0.75 | AF12: 1.76 | AG12: 3.89 | AH12: =(AG12/100)*100000 -> 3890 | AI12: 12.44 | AJ12: 87.37 | AK12: 14.81 | AL12: 85.13 | AM12: =(AK12/100)*(AH12) -> 576.109 | AN12: =(AL12/100)*(AH12) -> 3311.557 | AO12: 12.463681 | AP12: 14.818891 | AR12: =AP12/$AQ$4 -> 1.3743282 | AS12: 0.75 | AT12: 1.45 | AU12: 2.93 | AV12: 27.03 | AW12: 72.9 | AX12: 2.93 | AY12: 31.44 | AZ12: 68.36 | BA12: 31.503006 | BB12: 92548 | BC12: 140 | BD12: 674 | BE12: 127 | BF12: 1568 | BG12: 1370 | BH12: 195 | BI12: 29 | BJ12: 3390 | BK12: 502 | BL12: 2886 | BM12: 170 | BN12: 1295 | BO12: 944 | BP12: 350 | BQ12: 2573 | BR12: 1759 | BS12: 809 | BT12: 21 | BU12: 748
A13: 10 | B13: SC | C13: TEST | D13: 2 | E13: 45621 | F13: 4 | G13: 4 | H13: 5.71 | I13: 0 | J13: 0 | K13: 0 | O13: 100000 | P13: 17.1 | Q13: =(O13)/(P13) -> 5847.9532 | R13: 100000 | S13: 8.1 | T13: =(R13)/(S13) -> 12345.679 | W13: 8370.65 | X13: 0.02 | Y13: 0.03 | Z13: 0.05 | AA13: 1.7699115 | AB13: 4.7619048 | AC13: 4.6728972 | AD13: 0.2 | AE13: 1.13 | AF13: 0.63 | AG13: 1.07 | AH13: =(AG13/100)*100000 -> 1070 | AI13: 8.95 | AJ13: 90.53 | AK13: 9.77 | AL13: 89.71 | AM13: =(AK13/100)*(AH13) -> 104.539 | AN13: =(AL13/100)*(AH13) -> 959.897 | AO13: 8.9967833 | AP13: 9.8210696 | AR13: =AP13/$AQ$4 -> 0.91082206 | AS13: 1.13 | AT13: 0.73 | AU13: 1.06 | AV13: 8.32 | AW13: 91.52 | AX13: 1.06 | AY13: 9.07 | AZ13: 90.4 | BA13: 9.1183271 | BB13: 96324 | BC13: 186 | BF13: 570 | BG13: 516 | BH13: 51 | BI13: 29 | BJ13: 952 | BK13: 93 | BL13: 854 | BM13: 47 | BN13: 637 | BO13: 583 | BP13: 53 | BQ13: 948 | BR13: 857 | BS13: 86 | BT13: 42 | BU13: 735 | BV13: 103 | BW13: 100 | BX13: 102 | CC13: 23 | CD13: 38 | CE13: 64.07767 | CF13: 37 | CG13: 28 | CK13: 23.300971 | CL13: 28 | CM13: 28 | CQ13: 8.7378641 | CR13: 10 | CS13: 4 | CT13: 3.8834951 | CU13: 2 | CV13: 4
A14: 11 | B14: SC | C14: TEST | D14: 2 | E14: 45621 | F14: 4 | G14: 0 | H14: 1.84 | I14: 1 | J14: 1 | K14: 0 | L14: 100000 | M14: 6.7 | N14: =(L14)/(M14) -> 14925.373 | O14: 100000 | P14: 6.4 | Q14: =(O14)/(P14) -> 15625 | R14: 100000 | S14: 4.3 | T14: =(R14)/(S14) -> 23255.814 | U14: 1.7228261 | V14: 11661.35 | W14: 11329.58 | X14: 0.25 | Y14: 0.09 | Z14: 0.53 | AA14: 13.586957 | AB14: 2.7027027 | AC14: 9.2495637 | AD14: 1.3 | AE14: 1.84 | AF14: 3.33 | AG14: 5.73 | AH14: =(AG14/100)*100000 -> 5730 | AI14: 5.36 | AJ14: 94.48 | AK14: 6.15 | AL14: 93.7 | AM14: =(AK14/100)*(AH14) -> 352.395 | AN14: =(AL14/100)*(AH14) -> 5369.01 | AO14: 5.3685897 | AP14: 6.1592389 | AR14: =AP14/$AQ$4 -> 0.57121789 | AS14: 1.84 | AT14: 2.43 | AU14: 4.73 | AV14: 11.97 | AW14: 87.74 | AX14: 4.73 | AY14: 14.67 | AZ14: 84.76 | BA14: 14.754098 | BB14: 60161 | BC14: 705 | BD14: 971 | BE14: 130 | BF14: 1903 | BG14: 1798 | BH14: 102 | BI14: 52 | BJ14: 3318 | BK14: 204 | BL14: 3109 | BM14: 307 | BN14: 1378 | BO14: 1209 | BP14: 165 | BQ14: 2782 | BR14: 2358 | BS14: 408 | BT14: 16 | BU14: 870 | BV14: 106 | BW14: 143 | BX14: 101 | CC14: 18 | CD14: 27 | CE14: 51.886792 | CF14: 24 | CG14: 18 | CK14: 21.698113 | CL14: 84 | CM14: 33 | CQ14: 6.6037736 | CR14: 9 | CS14: 7 | CT14: 19.811321 | CU14: 8 | CV14: 16
A15: 12 | B15: SS | C15: TEST | D15: 2 | E15: 45621 | F15: 3 | G15: 1 | H15: 4.62 | I15: 0 | J15: 1 | K15: 0 | L15: 100000 | M15: 7.5 | N15: =(L15)/(M15) -> 13333.333 | O15: 100000 | P15: 7.2 | Q15: =(O15)/(P15) -> 13888.889 | R15: 100000 | S15: 4.8 | T15: =(R15)/(S15) -> 20833.333 | U15: 3.9152542 | V15: 17682.19 | W15: 17369.13 | X15: 0.17 | Y15: 0.07 | Z15: 0.42 | AA15: 28.813559 | AB15: 5.6 | AC15: 16.40625 | AD15: 0.24 | AE15: 0.59 | AF15: 1.25 | AG15: 2.56 | AH15: =(AG15/100)*100000 -> 2560 | AI15: 8.84 | AJ15: 91.07 | AK15: 7.78 | AL15: 92.09 | AM15: =(AK15/100)*(AH15) -> 199.168 | AN15: =(AL15/100)*(AH15) -> 2357.504 | AO15: 8.8479632 | AP15: 7.7901272 | AR15: =AP15/$AQ$4 -> 0.72246914 | AS15: 0.59 | AT15: 1.15 | AU15: 2.2 | AV15: 16.65 | AW15: 83.16 | AX15: 2.2 | AY15: 20.38 | AZ15: 79.32 | BA15: 20.441324 | BB15: 95235 | BC15: 232 | BD15: 521 | BE15: 155 | BF15: 1165 | BG15: 1061 | BH15: 103 | BI15: 64 | BJ15: 2338 | BK15: 182 | BL15: 2153 | BM15: 384 | BN15: 1063 | BO15: 884 | BP15: 177 | BQ15: 1963 | BR15: 1557 | BS15: 400 | BT15: 43 | BU15: 930 | BV15: 123 | BW15: 101 | BX15: 109 | CC15: 3 | CD15: 18 | CE15: 32.520325 | CF15: 8 | CG15: 9 | CK15: 28.455285 | CL15: 51 | CM15: 44 | CQ15: 12.195122 | CR15: 26 | CS15: 15 | CT15: 26.829268 | CU15: 13 | CV15: 24
A16: 13 | B16: SS | C16: TEST | D16: 2 | E16: 45621 | F16: 3 | G16: 0 | H16: 1.44 | I16: 0 | J16: 1 | K16: 0 | L16: 100000 | M16: 7.4 | N16: =(L16)/(M16) -> 13513.514 | O16: 100000 | P16: 8.2 | Q16: =(O16)/(P16) -> 12195.122 | R16: 100000 | S16: 6 | T16: =(R16)/(S16) -> 16666.667 | U16: 3.9852941 | V16: 15119.22 | W16: 16178.82 | X16: 0.14 | Y16: 0.07 | Z16: 0.47 | AA16: 20.588235 | AB16: 4.7619048 | AC16: 15.25974 | AD16: 0.18 | AE16: 0.68 | AF16: 1.47 | AG16: 3.08 | AH16: =(AG16/100)*100000 -> 3080 | AI16: 7.58 | AJ16: 92.05 | AK16: 7.14 | AL16: 92.53 | AM16: =(AK16/100)*(AH16) -> 219.912 | AN16: =(AL16/100)*(AH16) -> 2849.924 | AO16: 7.6081502 | AP16: 7.16364 | AR16: =AP16/$AQ$4 -> 0.66436769 | AS16: 0.68 | AT16: 1.32 | AU16: 2.66 | AV16: 20.8 | AW16: 79.11 | AX16: 2.66 | AY16: 16.2 | AZ16: 83.71 | BA16: 16.214593 | BB16: 91005 | BC16: 160 | BD16: 636 | BE16: 135 | BF16: 1320 | BG16: 1215 | BH16: 100 | BI16: 63 | BJ16: 2744 | BK16: 196 | BL16: 2539 | BM16: 420 | BN16: 1173 | BO16: 928 | BP16: 244 | BQ16: 2302 | BR16: 1927 | BS16: 373 | BT16: 17 | BU16: 1178 | BV16: 110 | BW16: 100 | BX16: 103 | CC16: 5 | CD16: 17 | CE16: 30 | CF16: 8 | CG16: 14 | CK16: 20 | CL16: 60 | CM16: 50 | CQ16: 16.363636 | CR16: 22 | CS16: 9 | CT16: 33.636364 | CU16: 5 | CV16: 13
A17: 14 | B17: AA CTRL | C17: CTRL FRESH | D17: 3 | E17: 45635 | F17: 0 | G17: 0 | H17: 0.37 | I17: 1 | J17: 2 | K17: 0 | L17: 100000 | M17: 2.5 | N17: =(L17)/(M17) -> 40000 | O17: 100000 | P17: 2.3 | Q17: =(O17)/(P17) -> 43478.261 | R17: 100000 | S17: 3.7 | T17: =(R17)/(S17) -> 27027.027 | U17: 6 | V17: 9986.37 | W17: 11830.04 | X17: 0.06 | Y17: 0.05 | Z17: 0.63 | AA17: 11.320755 | AB17: 2.0242915 | AC17: 19.811321 | AD17: 0.32 | AE17: 0.53 | AF17: 2.47 | AG17: 3.18 | AH17: =(AG17/100)*100000 -> 3180 | AI17: 5.21 | AJ17: 94.79 | AK17: 9.01 | AL17: 90.64 | AM17: =(AK17/100)*(AH17) -> 286.518 | AN17: =(AL17/100)*(AH17) -> 2882.352 | AO17: 5.21 | AP17: 9.0416458 | AS17: 0.53 | AT17: 1.69 | AU17: 2.15 | AV17: 24.44 | AW17: 75.37 | AX17: 34.45 | AY17: 65 | AZ17: 24.486524 | BA17: 34.640523 | BB17: 89881 | BC17: 283 | BD17: 476 | BE17: 54 | BF17: 2225 | BG17: 2109 | BH17: 116 | BI17: 47 | BJ17: 2886 | BK17: 2616 | BL17: 260 | BM17: 570 | BN17: 1571 | BO17: 1184 | BP17: 384 | BQ17: 2000 | BR17: 1300 | BS17: 689 | BT17: 5 | BU17: 1338
A18: 15 | B18: AA | C18: TEST | D18: 3 | E18: 45635 | F18: 0 | G18: 4 | H18: 1.47 | I18: 1 | J18: 0 | K18: 0 | L18: 100000 | M18: 3.7 | N18: =(L18)/(M18) -> 27027.027 | O18: 100000 | P18: 2.5 | Q18: =(O18)/(P18) -> 40000 | R18: 100000 | S18: 4.6 | T18: =(R18)/(S18) -> 21739.13 | U18: 5.630137 | V18: 8885.82 | W18: 12132.97 | X18: 0.06 | Y18: 0 | Z18: 0.86 | AA18: 8.2191781 | AB18: 0 | AC18: 20.924574 | AD18: 0.39 | AE18: 0.73 | AF18: 3.37 | AG18: 4.11 | AH18: =(AG18/100)*100000 -> 4110 | AI18: 7.58 | AJ18: 92.38 | AK18: 14.13 | AL18: 85.46 | AM18: =(AK18/100)*(AH18) -> 580.743 | AN18: =(AL18/100)*(AH18) -> 3512.406 | AO18: 7.5830332 | AP18: 14.188172 | AS18: 0.73 | AT18: 2.57 | AU18: 3.64 | AV18: 28.74 | AW18: 70.73 | AX18: 37.1 | AY18: 62.66 | AZ18: 28.893134 | BA18: 37.189254 | BB18: 89653 | BC18: 345 | BD18: 645 | BE18: 49 | BF18: 2941 | BG18: 2717 | BH18: 223 | BI18: 0 | BJ18: 3644 | BK18: 3114 | BL18: 515 | BM18: 761 | BN18: 2279 | BO18: 1612 | BP18: 655 | BQ18: 3251 | BR18: 2037 | BS18: 1206 | BT18: 13 | BU18: 885
A19: 16 | B19: AA | C19: TEST | D19: 3 | E19: 45635 | F19: 0 | G19: 3 | H19: 1.52 | I19: 0 | J19: 0 | K19: 0 | L19: 100000 | M19: 10.8 | N19: =(L19)/(M19) -> 9259.2593 | O19: 100000 | P19: 9.3 | Q19: =(O19)/(P19) -> 10752.688 | R19: 100000 | S19: 13.5 | T19: =(R19)/(S19) -> 7407.4074 | U19: 3.3455497 | V19: 12335.99 | W19: 17197.04 | X19: 0.42 | Y19: 0.1 | Z19: 2.28 | AA19: 21.989529 | AB19: 1.6806723 | AC19: 35.680751 | AD19: 0.94 | AE19: 1.91 | AF19: 5.95 | AG19: 6.39 | AH19: =(AG19/100)*100000 -> 6390 | AI19: 6.5 | AJ19: 93.37 | AK19: 10.76 | AL19: 89.03 | AM19: =(AK19/100)*(AH19) -> 687.564 | AN19: =(AL19/100)*(AH19) -> 5689.017 | AO19: 6.508461 | AP19: 10.782644 | AS19: 1.91 | AT19: 4.34 | AU19: 7.02 | AV19: 30.04 | AW19: 69.86 | AX19: 35.48 | AY19: 64.44 | AZ19: 30.07007 | BA19: 35.508407 | BB19: 92140 | BC19: 861 | BD19: 1778 | BE19: 392 | BF19: 5552 | BG19: 5184 | BH19: 361 | BI19: 91 | BJ19: 5987 | BK19: 5330 | BL19: 644 | BM19: 2137 | BN19: 4081 | BO19: 2851 | BP19: 1226 | BQ19: 6434 | BR19: 4146 | BS19: 2283 | BT19: 8 | BU19: 528
A20: 17 | B20: AA | C20: TEST | D20: 3 | E20: 45635 | F20: 0 | G20: 3 | H20: 1.42 | I20: 1 | J20: 0 | K20: 1 | O20: 100000 | P20: 10 | Q20: =(O20)/(P20) -> 10000 | R20: 100000 | S20: 11.1 | T20: =(R20)/(S20) -> 9009.009 | W20: 12071.72 | X20: 0.56 | Y20: 0.03 | Z20: 0.47 | AA20: 45.16129 | AB20: 1.6574586 | AC20: 18.7251 | AD20: 0.45 | AE20: 1.24 | AF20: 1.81 | AG20: 2.51 | AH20: =(AG20/100)*100000 -> 2510 | AI20: 6.91 | AJ20: 93.03 | AK20: 9.32 | AL20: 90.47 | AM20: =(AK20/100)*(AH20) -> 233.932 | AN20: =(AL20/100)*(AH20) -> 2270.797 | AO20: 6.9141485 | AP20: 9.3396132 | AS20: 1.24 | AT20: 2.57 | AU20: 3.05 | AV20: 24.01 | AW20: 75.86 | AX20: 36.24 | AY20: 63.55 | AZ20: 24.041254 | BA20: 36.316264 | BB20: 93941 | BC20: 422 | BF20: 1707 | BG20: 1588 | BH20: 118 | BI20: 28 | BJ20: 2339 | BK20: 2116 | BL20: 218 | BM20: 436 | BN20: 2403 | BO20: 1823 | BP20: 577 | BQ20: 2845 | BR20: 1808 | BS20: 1031 | BT20: 13 | BU20: 918
A21: 18 | B21: AC | C21: TEST | D21: 3 | E21: 45635 | F21: 1 | G21: 0 | H21: 0.57 | I21: 0 | J21: 0 | K21: 0 | L21: 100000 | M21: 7.3 | N21: =(L21)/(M21) -> 13698.63 | O21: 100000 | P21: 3.1 | Q21: =(O21)/(P21) -> 32258.065 | R21: 100000 | S21: 4 | T21: =(R21)/(S21) -> 25000 | U21: 3.3628319 | V21: 9904.87 | W21: 10180.22 | X21: 0.08 | Y21: 0.09 | Z21: 0.53 | AA21: 7.079646 | AB21: 2.4523161 | AC21: 13.947368 | AD21: 0.17 | AE21: 1.13 | AF21: 3.67 | AG21: 3.8 | AH21: =(AG21/100)*100000 -> 3800 | AI21: 6.5 | AJ21: 93.41 | AK21: 13.3 | AL21: 86.53 | AM21: =(AK21/100)*(AH21) -> 505.4 | AN21: =(AL21/100)*(AH21) -> 3288.14 | AO21: 6.5058553 | AP21: 13.322649 | AR21: =AP21/$AQ$4 -> 1.2355642 | AS21: 1.13 | AT21: 1.9 | AU21: 2.92 | AV21: 30.7 | AW21: 69.01 | AX21: 36.73 | AY21: 63.16 | AZ21: 30.789289 | BA21: 36.770447 | BB21: 92439 | BC21: 152 | BD21: 827 | BE21: 59 | BF21: 3263 | BG21: 3048 | BH21: 212 | BI21: 78 | BJ21: 3414 | BK21: 2954 | BL21: 454 | BM21: 476 | BN21: 1736 | BO21: 1198 | BP21: 533 | BQ21: 2592 | BR21: 1637 | BS21: 952 | BT21: 8 | BU21: 1413
A22: 19 | B22: AS | C22: TEST | D22: 3 | E22: 45635 | F22: 2 | G22: 0 | H22: 0.6 | I22: 1 | J22: 0 | K22: 1 | O22: 100000 | P22: 9 | Q22: =(O22)/(P22) -> 11111.111 | R22: 100000 | S22: 9.8 | T22: =(R22)/(S22) -> 10204.082 | U22: 3.9756098 | V22: 7332.6 | W22: 6919.84 | X22: 0.11 | Y22: 0.04 | Z22: 0.16 | AA22: 8.9430894 | AB22: 1.4336918 | AC22: 3.2719836 | AD22: 0.42 | AE22: 1.23 | AF22: 2.79 | AG22: 4.89 | AH22: =(AG22/100)*100000 -> 4890 | AI22: 12.73 | AJ22: 87.15 | AK22: 14.01 | AL22: 85.9 | AM22: =(AK22/100)*(AH22) -> 685.089 | AN22: =(AL22/100)*(AH22) -> 4200.51 | AO22: 12.745294 | AP22: 14.02262 | AR22: =AP22/$AQ$4 -> 1.3004807 | AS22: 1.23 | AT22: 2.62 | AU22: 4.88 | AV22: 26.46 | AW22: 73.41 | AX22: 30.46 | AY22: 69.43 | AZ22: 26.494443 | BA22: 30.493543 | BB22: 89732 | BC22: 369 | BD22: 1112 | BE22: 97 | BF22: 2530 | BG22: 2205 | BH22: 322 | BI22: 32 | BJ22: 4468 | BK22: 3838 | BL22: 626 | BM22: 149 | BN22: 2343 | BO22: 1720 | BP22: 620 | BQ22: 4288 | BR22: 2977 | BS22: 1306 | BT22: 11 | BU22: 1843
A23: 20 | B23: SS | C23: TEST | D23: 3 | E23: 45635 | F23: 3 | G23: 3 | H23: 5.61 | I23: 1 | J23: 1 | K23: 0 | L23: 100000 | M23: 4.4 | N23: =(L23)/(M23) -> 22727.273 | O23: 100000 | P23: 4.6 | Q23: =(O23)/(P23) -> 21739.13 | R23: 100000 | S23: 4.1 | T23: =(R23)/(S23) -> 24390.244 | U23: 4.3636364 | V23: 7817.38 | W23: 9694.16 | X23: 0.05 | Y23: 0.04 | Z23: 0.33 | AA23: 7.5757576 | AB23: 1.8691589 | AC23: 11.458333 | AD23: 0.29 | AE23: 0.66 | AF23: 2.14 | AG23: 2.88 | AH23: =(AG23/100)*100000 -> 2880 | AI23: 4.33 | AJ23: 95.51 | AK23: 5.02 | AL23: 94.83 | AM23: =(AK23/100)*(AH23) -> 144.576 | AN23: =(AL23/100)*(AH23) -> 2731.104 | AO23: 4.3369391 | AP23: 5.0275413 | AR23: =AP23/$AQ$4 -> 0.4662624 | AS23: 0.66 | AT23: 1.46 | AU23: 1.95 | AV23: 18.05 | AW23: 81.72 | AX23: 19.88 | AY23: 79.73 | AZ23: 18.091611 | BA23: 19.957836 | BB23: 86967 | BC23: 244 | BD23: 577 | BE23: 43 | BF23: 1894 | BG23: 1809 | BH23: 82 | BI23: 34 | BJ23: 2532 | BK23: 2401 | BL23: 127 | BM23: 290 | BN23: 1313 | BO23: 1073 | BP23: 237 | BQ23: 1776 | BR23: 1416 | BS23: 353 | BT23: 82 | BU23: 1463
A24: 21 | B24: SS | C24: TEST | D24: 3 | E24: 45635 | F24: 3 | G24: 0 | H24: 4.48 | I24: 0 | J24: 1 | K24: 0 | L24: 100000 | M24: 4.2 | N24: =(L24)/(M24) -> 23809.524 | O24: 100000 | P24: 4.4 | Q24: =(O24)/(P24) -> 22727.273 | R24: 100000 | S24: 3.9 | T24: =(R24)/(S24) -> 25641.026 | U24: 5.2295082 | V24: 8202.84 | W24: 8616.26 | X24: 0.06 | Y24: 0.04 | Z24: 0.34 | AA24: 9.8360656 | AB24: 1.8099548 | AC24: 10.658307 | AD24: 0.21 | AE24: 0.61 | AF24: 2.21 | AG24: 3.19 | AH24: =(AG24/100)*100000 -> 3190 | AI24: 6.51 | AJ24: 93.09 | AK24: 6.67 | AL24: 93.01 | AM24: =(AK24/100)*(AH24) -> 212.773 | AN24: =(AL24/100)*(AH24) -> 2967.019 | AO24: 6.5361446 | AP24: 6.6914125 | AR24: =AP24/$AQ$4 -> 0.62057254 | AS24: 0.61 | AT24: 1.53 | AU24: 2.12 | AV24: 15.28 | AW24: 84.58 | AX24: 17.93 | AY24: 81.77 | AZ24: 15.301422 | BA24: 17.983952 | BB24: 91233 | BC24: 186 | BE24: 50 | BF24: 1997 | BG24: 1859 | BH24: 130 | BI24: 33 | BJ24: 2863 | BK24: 2663 | BL24: 191 | BM24: 305 | BN24: 1394 | BO24: 1179 | BP24: 213 | BQ24: 1947 | BR24: 1592 | BS24: 349 | BT24: 62 | BU24: 1383
A25: 22 | B25: AA CTRL | C25: CTRL FRESH | D25: 4 | E25: 45645 | F25: 0 | G25: 0 | H25: 0.21 | I25: 1 | J25: 2 | K25: 0 | L25: 100000 | M25: 3 | N25: =(L25)/(M25) -> 33333.333 | O25: 100000 | P25: 2.8 | Q25: =(O25)/(P25) -> 35714.286 | R25: 100000 | S25: 2.8 | T25: =(R25)/(S25) -> 35714.286 | U25: 4.9279279 | V25: 21865.8 | W25: 10291.49 | X25: 0.5 | Y25: 0.2 | Z25: 0.71 | AA25: 50 | AB25: 5.0890585 | AC25: 12.97989 | AD25: 0.98 | AE25: 1.11 | AF25: 3.93 | AG25: 5.47 | AH25: =(AG25/100)*100000 -> 5470 | AI25: 10.4 | AJ25: 89.43 | AK25: 8.49 | AL25: 91.27 | AM25: =(AK25/100)*(AH25) -> 464.403 | AN25: =(AL25/100)*(AH25) -> 4992.469 | AO25: 10.41771 | AP25: 8.510425 | AS25: 1.11 | AT25: 1.76 | AU25: 2.98 | AV25: 22.55 | AW25: 77.39 | AX25: 34.64 | AY25: 65.16 | AZ25: 22.563538 | BA25: 34.709419 | BB25: 88982 | BC25: 866 | BD25: 91303 | BE25: 455 | BF25: 3586 | BG25: 3207 | BH25: 373 | BI25: 4 | BJ25: 5019 | BK25: 4581 | BL25: 426 | BM25: 21 | BN25: 1650 | BO25: 1277 | BP25: 372 | BQ25: 3014 | BR25: 1964 | BS25: 1044 | BT25: 3 | BU25: 1458
A26: 23 | B26: AA CTRL | C26: CTRL CRYO | D26: 4 | E26: 45645 | F26: 0 | G26: 0 | H26: 0.69 | I26: 1 | J26: 2 | K26: 0 | L26: 100000 | M26: 4.2 | N26: =(L26)/(M26) -> 23809.524 | O26: 100000 | P26: 3.5 | Q26: =(O26)/(P26) -> 28571.429 | R26: 100000 | S26: 2.1 | T26: =(R26)/(S26) -> 47619.048 | U26: 6.1774194 | V26: 19441.64 | W26: 10737.74 | X26: 0.24 | Y26: 0.16 | Z26: 0.55 | AA26: 42.857143 | AB26: 5.5363322 | AC26: 14.360313 | AD26: 0.47 | AE26: 0.62 | AF26: 2.89 | AG26: 3.83 | AH26: =(AG26/100)*100000 -> 3830 | AI26: 7.95 | AJ26: 91.98 | AK26: 7.7 | AL26: 92.1 | AM26: =(AK26/100)*(AH26) -> 294.91 | AN26: =(AL26/100)*(AH26) -> 3527.43 | AO26: 7.9555689 | AP26: 7.7154309 | AS26: 0.62 | AT26: 1.31 | AU26: 1.79 | AV26: 22.73 | AW26: 76.78 | AX26: 30.32 | AY26: 69.07 | AZ26: 22.841925 | BA26: 30.506087 | BB26: 90417 | BC26: 422 | BD26: 92010 | BE26: 222 | BF26: 2617 | BG26: 2407 | BH26: 208 | BI26: 3 | BJ26: 3468 | BK26: 3194 | BL26: 267 | BM26: 24 | BN26: 1236 | BO26: 949 | BP26: 281 | BQ26: 1814 | BR26: 1253 | BS26: 550 | BT26: 11 | BU26: 1588
A27: 24 | B27: AA CTRL | C27: CTRL CRYO | D27: 4 | E27: 45645 | F27: 0 | G27: 0 | H27: 0.19 | I27: 1 | J27: 2 | K27: 0 | L27: 100000 | M27: 3 | N27: =(L27)/(M27) -> 33333.333 | O27: 100000 | P27: 4.1 | Q27: =(O27)/(P27) -> 24390.244 | R27: 100000 | S27: 3.7 | T27: =(R27)/(S27) -> 27027.027 | U27: 6.2653061 | V27: 17811.81 | W27: 10366.4 | X27: 0.18 | Y27: 0.11 | Z27: 0.39 | AA27: 40.909091 | AB27: 5.0691244 | AC27: 12.703583 | AD27: 0.35 | AE27: 0.49 | AF27: 2.17 | AG27: 3.07 | AH27: =(AG27/100)*100000 -> 3070 | AI27: 7.08 | AJ27: 92.72 | AK27: 6.8 | AL27: 92.95 | AM27: =(AK27/100)*(AH27) -> 208.76 | AN27: =(AL27/100)*(AH27) -> 2853.565 | AO27: 7.0941884 | AP27: 6.8170426 | AS27: 0.49 | AT27: 1.39 | AU27: 1.26 | AV27: 15.55 | AW27: 84.15 | AX27: 32.78 | AY27: 66.67 | AZ27: 15.59679 | BA27: 32.961287 | BB27: 92385 | BC27: 325 | BD27: 91803 | BE27: 163 | BF27: 1992 | BG27: 1847 | BH27: 141 | BI27: 2 | BJ27: 2780 | BK27: 2584 | BL27: 189 | BM27: 8 | BN27: 1312 | BO27: 1104 | BP27: 204 | BQ27: 1266 | BR27: 844 | BS27: 415 | BT27: 3 | BU27: 1585
A28: 25 | B28: AA | C28: TEST | D28: 4 | E28: 45645 | F28: 0 | G28: 0 | H28: 1.18 | I28: 1 | J28: 0 | K28: 0 | O28: 100000 | P28: 13.2 | Q28: =(O28)/(P28) -> 7575.7576 | R28: 100000 | S28: 14.9 | T28: =(R28)/(S28) -> 6711.4094 | U28: 1.2959184 | W28: 16369.23 | X28: 0.69 | Y28: 0.09 | Z28: 0.31 | AA28: 70.408163 | AB28: 5.2941176 | AC28: 24.409449 | AD28: 0.84 | AE28: 0.98 | AF28: 1.7 | AG28: 1.27 | AH28: =(AG28/100)*100000 -> 1270 | AI28: 7.88 | AJ28: 92 | AK28: 10.37 | AL28: 88.95 | AM28: =(AK28/100)*(AH28) -> 131.699 | AN28: =(AL28/100)*(AH28) -> 1129.665 | AO28: 7.8894674 | AP28: 10.440999 | AS28: 0.98 | AT28: 2.59 | AU28: 1.2 | AV28: 14.05 | AW28: 85.12 | AX28: 21.85 | AY28: 77.48 | AZ28: 14.167591 | BA28: 21.997382 | BB28: 95781 | BC28: 796 | BF28: 1600 | BG28: 1472 | BH28: 126 | BI28: 6 | BJ28: 1186 | BK28: 1055 | BL28: 123 | BM28: 12 | BN28: 121 | BO28: 103 | BP28: 17 | BQ28: 1208 | BR28: 936 | BS28: 264 | BT28: 21 | BU28: 1780
A29: 26 | B29: AC | C29: TEST | D29: 4 | E29: 45645 | F29: 1 | G29: 2 | H29: 1.21 | I29: 1 | J29: 0 | K29: 1 | O29: 100000 | P29: 25.2 | Q29: =(O29)/(P29) -> 3968.254 | R29: 100000 | S29: 37.3 | T29: =(R29)/(S29) -> 2680.9651 | U29: 1.9759615 | W29: 17836.7 | X29: 1.2 | Y29: 0.19 | Z29: 1.13 | AA29: 57.692308 | AB29: 4.5783133 | AC29: 27.493917 | AD29: 2 | AE29: 2.08 | AF29: 4.15 | AG29: 4.11 | AH29: =(AG29/100)*100000 -> 4110 | AI29: 13.64 | AJ29: 86.28 | AK29: 17.71 | AL29: 81.94 | AM29: =(AK29/100)*(AH29) -> 727.881 | AN29: =(AL29/100)*(AH29) -> 3367.734 | AO29: 13.650921 | AP29: 17.772203 | AR29: =AP29/$AQ$4 -> 1.6482231 | AS29: 2.08 | AT29: 43.3 | AU29: 4.92 | AV29: 30.94 | AW29: 64.75 | AX29: 41.62 | AY29: 58.2 | AZ29: 32.333577 | BA29: 41.695051 | BB29: 94067 | BC29: 3301 | BF29: 3863 | BG29: 3333 | BH29: 527 | BI29: 14 | BJ29: 3738 | BK29: 3063 | BL29: 662 | BM29: 59 | BN29: 139 | BO29: 90 | BP29: 43 | BQ29: 4983 | BR29: 2900 | BS29: 2074 | BT29: 16 | BU29: 1323
A30: 27 | B30: SS | C30: TEST | D30: 4 | E30: 45645 | F30: 3 | G30: 1 | H30: 6.31 | I30: 0 | J30: 1 | K30: 0 | L30: 100000 | M30: 7 | N30: =(L30)/(M30) -> 14285.714 | O30: 100000 | P30: 4.5 | Q30: =(O30)/(P30) -> 22222.222 | R30: 100000 | S30: 4.4 | T30: =(R30)/(S30) -> 22727.273 | U30: 2.3647059 | V30: 7205.75 | W30: 5525.86 | X30: 0.04 | Y30: 0.1 | Z30: 0.04 | AA30: 4.7058824 | AB30: 3.3333333 | AC30: 1.9900498 | AD30: 0.77 | AE30: 0.85 | AF30: 3 | AG30: 2.01 | AH30: =(AG30/100)*100000 -> 2010 | AI30: 27.72 | AJ30: 71.99 | AK30: 6.74 | AL30: 92.98 | AM30: =(AK30/100)*(AH30) -> 135.474 | AN30: =(AL30/100)*(AH30) -> 1868.898 | AO30: 27.800622 | AP30: 6.758925 | AR30: =AP30/$AQ$4 -> 0.62683376 | AS30: 0.85 | AT30: 1.44 | AU30: 1.5 | AV30: 10.37 | AW30: 89.24 | AX30: 15.95 | AY30: 83.46 | AZ30: 10.410601 | BA30: 16.044664 | BB30: 88077 | BC30: 654 | BD30: 91096 | BE30: 38 | BF30: 2810 | BG30: 2023 | BH30: 779 | BI30: 6 | BJ30: 1795 | BK30: 1669 | BL30: 121 | BM30: 3 | BN30: 1292 | BO30: 1153 | BP30: 134 | BQ30: 1505 | BR30: 1256 | BS30: 240 | BT30: 85 | BU30: 1348
A31: 28 | B31: SS | C31: TEST | D31: 4 | E31: 45645 | F31: 3 | G31: 0 | H31: 4.81 | I31: 0 | J31: 1 | K31: 0 | L31: 100000 | M31: 7.6 | N31: =(L31)/(M31) -> 13157.895 | O31: 100000 | P31: 8.4 | Q31: =(O31)/(P31) -> 11904.762 | R31: 100000 | S31: 6.3 | T31: =(R31)/(S31) -> 15873.016 | U31: 1.9054054 | V31: 5752.31 | W31: 5413.15 | X31: 0.02 | Y31: 0.02 | Z31: 0.03 | AA31: 2.7027027 | AB31: 1.6129032 | AC31: 2.1276596 | AD31: 0.87 | AE31: 0.74 | AF31: 1.24 | AG31: 1.41 | AH31: =(AG31/100)*100000 -> 1410 | AI31: 5.99 | AJ31: 93.64 | AK31: 4.9 | AL31: 94.61 | AM31: =(AK31/100)*(AH31) -> 69.09 | AN31: =(AL31/100)*(AH31) -> 1334.001 | AO31: 6.0122453 | AP31: 4.9241282 | AR31: =AP31/$AQ$4 -> 0.45667171 | AS31: 0.74 | AT31: 1.03 | AU31: 1.05 | AV31: 5.62 | AW31: 94.15 | AX31: 7.1 | AY31: 92.05 | AZ31: 5.6329558 | BA31: 7.1608674 | BB31: 85739 | BC31: 714 | BD31: 87704 | BE31: 19 | BF31: 1069 | BG31: 1001 | BH31: 64 | BI31: 3 | BJ31: 1224 | BK31: 1158 | BL31: 60 | BM31: 2 | BN31: 889 | BO31: 837 | BP31: 50 | BQ31: 1057 | BR31: 973 | BS31: 75 | BT31: 81 | BU31: 1685
A32: 29 | B32: SS | C32: TEST | D32: 4 | E32: 45645 | F32: 3 | G32: 0 | H32: 6.72 | I32: 1 | J32: 1 | K32: 0 | L32: 100000 | M32: 7.7 | N32: =(L32)/(M32) -> 12987.013 | O32: 100000 | P32: 10.3 | Q32: =(O32)/(P32) -> 9708.7379 | R32: 100000 | S32: 8.7 | T32: =(R32)/(S32) -> 11494.253 | U32: 1.7230769 | V32: 5922.45 | W32: 5773.56 | X32: 0.01 | Y32: 0.02 | Z32: 0.04 | AA32: 1.5384615 | AB32: 2.1276596 | AC32: 3.5714286 | AD32: 0.82 | AE32: 0.65 | AF32: 0.94 | AG32: 1.12 | AH32: =(AG32/100)*100000 -> 1120 | AI32: 17.59 | AJ32: 81.72 | AK32: 15.36 | AL32: 83.86 | AM32: =(AK32/100)*(AH32) -> 172.032 | AN32: =(AL32/100)*(AH32) -> 939.232 | AO32: 17.712214 | AP32: 15.48075 | AR32: =AP32/$AQ$4 -> 1.4357101 | AS32: 0.65 | AT32: 0.92 | AU32: 0.93 | AV32: 20.52 | AW32: 79.02 | AX32: 19.94 | AY32: 79.31 | AZ32: 20.614828 | BA32: 20.09068 | BB32: 90781 | BC32: 731 | BD32: 94418 | BE32: 7 | BF32: 870 | BG32: 711 | BH32: 153 | BI32: 9 | BJ32: 1035 | BK32: 868 | BL32: 159 | BM32: 10 | BN32: 853 | BO32: 674 | BP32: 175 | BQ32: 933 | BR32: 740 | BS32: 186 | BT32: 115 | BU32: 1713
A33: 30 | B33: SS | C33: TEST | D33: 4 | E33: 45645 | F33: 3 | G33: 0 | H33: 5.6 | I33: 0 | J33: 1 | K33: 1 | L33: 100000 | M33: 10.2 | N33: =(L33)/(M33) -> 9803.9216 | O33: 100000 | P33: 9 | Q33: =(O33)/(P33) -> 11111.111 | R33: 100000 | S33: 9.1 | T33: =(R33)/(S33) -> 10989.011 | U33: 2.2285714 | V33: 5943.54 | W33: 4949.46 | X33: 0.03 | Y33: 0.03 | Z33: 0.03 | AA33: 2.8571429 | AB33: 1.6483516 | AC33: 1.2820513 | AD33: 1.14 | AE33: 1.05 | AF33: 1.82 | AG33: 2.34 | AH33: =(AG33/100)*100000 -> 2340 | AI33: 7.01 | AJ33: 92.5 | AK33: 4.82 | AL33: 94.95 | AM33: =(AK33/100)*(AH33) -> 112.788 | AN33: =(AL33/100)*(AH33) -> 2221.83 | AO33: 7.0445181 | AP33: 4.8311116 | AR33: =AP33/$AQ$4 -> 0.44804519 | AS33: 1.05 | AT33: 1.73 | AU33: 1.87 | AV33: 9.43 | AW33: 90.5 | AX33: 9.03 | AY33: 90.38 | AZ33: 9.4366056 | BA33: 9.0835932 | BB33: 87103 | BC33: 955 | BD33: 90308 | BE33: 24 | BF33: 1627 | BG33: 1505 | BH33: 114 | BI33: 5 | BJ33: 2117 | BK33: 2010 | BL33: 102 | BM33: 2 | BN33: 1537 | BO33: 1391 | BP33: 145 | BQ33: 1882 | BR33: 1701 | BS33: 170 | BT33: 78 | BU33: 1393
A34: 31 | B34: SS | C34: TEST | D34: 4 | E34: 45645 | F34: 3 | G34: 1 | H34: 1.59 | I34: 0 | J34: 1 | K34: 0 | L34: 100000 | M34: 11.8 | N34: =(L34)/(M34) -> 8474.5763 | O34: 100000 | P34: 7.2 | Q34: =(O34)/(P34) -> 13888.889 | R34: 100000 | S34: 9.1 | T34: =(R34)/(S34) -> 10989.011 | U34: 2.7419355 | V34: 16232.47 | W34: 10233.56 | X34: 0.13 | Y34: 0.08 | Z34: 0.16 | AA34: 20.967742 | AB34: 6.0606061 | AC34: 9.4117647 | AD34: 0.72 | AE34: 0.62 | AF34: 1.32 | AG34: 1.7 | AH34: =(AG34/100)*100000 -> 1700 | AI34: 11.51 | AJ34: 88.49 | AK34: 10.76 | AL34: 88.97 | AM34: =(AK34/100)*(AH34) -> 182.92 | AN34: =(AL34/100)*(AH34) -> 1512.49 | AO34: 11.51 | AP34: 10.789131 | AR34: =AP34/$AQ$4 -> 1.0006016 | AS34: 0.62 | AT34: 1.32 | AU34: 0.96 | AV34: 14.43 | AW34: 84.9 | AX34: 22.42 | AY34: 76.64 | AZ34: 14.527333 | BA34: 22.632748 | BB34: 94702 | BC34: 666 | BD34: 97941 | BE34: 125 | BF34: 1190 | BG34: 1053 | BH34: 137 | BI34: 3 | BJ34: 1505 | BK34: 1339 | BL34: 162 | BM34: 4 | BN34: 1199 | BO34: 1018 | BP34: 173 | BQ34: 959 | BR34: 735 | BS34: 215 | BT34: 30 | BU34: 1893
A35: 32 | B35: SS | C35: TEST | D35: 4 | E35: 45645 | F35: 3 | G35: 0 | H35: 3.42 | I35: 0 | J35: 1 | K35: 0 | L35: 100000 | M35: 13.4 | N35: =(L35)/(M35) -> 7462.6866 | O35: 100000 | P35: 11 | Q35: =(O35)/(P35) -> 9090.9091 | R35: 100000 | S35: 11.9 | T35: =(R35)/(S35) -> 8403.3613 | U35: 4.1368421 | V35: 5496.15 | W35: 3814.94 | X35: 0.03 | Y35: 0.03 | Z35: 0.03 | AA35: 3.1578947 | AB35: 1.3333333 | AC35: 0.76335878 | AD35: 0.7 | AE35: 0.95 | AF35: 2.25 | AG35: 3.93 | AH35: =(AG35/100)*100000 -> 3930 | AI35: 8.77 | AJ35: 90.85 | AK35: 5.15 | AL35: 94.56 | AM35: =(AK35/100)*(AH35) -> 202.395 | AN35: =(AL35/100)*(AH35) -> 3716.208 | AO35: 8.8034531 | AP35: 5.1649784 | AR35: =AP35/$AQ$4 -> 0.47900855 | AS35: 0.95 | AT35: 2.15 | AU35: 3.13 | AV35: 11.24 | AW35: 88.26 | AX35: 7.77 | AY35: 91.79 | AZ35: 11.296482 | BA35: 7.8043391 | BB35: 89247 | BC35: 607 | BD35: 94786 | BE35: 27 | BF35: 2098 | BG35: 1906 | BH35: 184 | BI35: 13 | BJ35: 3692 | BK35: 3491 | BL35: 190 | BM35: 5 | BN35: 2001 | BO35: 1766 | BP35: 225 | BQ35: 3141 | BR35: 2883 | BS35: 244 | BT35: 50 | BU35: 1463
A36: 33 | B36: SS | C36: TEST | D36: 4 | E36: 45645 | F36: 3 | G36: 1 | H36: 1.28 | I36: 1 | J36: 1 | K36: 0 | L36: 100000 | M36: 9.3 | N36: =(L36)/(M36) -> 10752.688 | O36: 100000 | P36: 7.6 | Q36: =(O36)/(P36) -> 13157.895 | R36: 100000 | S36: 7.2 | T36: =(R36)/(S36) -> 13888.889 | U36: 3.9319728 | V36: 10153.86 | W36: 6650.39 | X36: 0.22 | Y36: 0.19 | Z36: 0.33 | AA36: 14.965986 | AB36: 4.2792793 | AC36: 5.7093426 | AD36: 1.12 | AE36: 1.47 | AF36: 4.44 | AG36: 5.78 | AH36: =(AG36/100)*100000 -> 5780 | AI36: 10.32 | AJ36: 88.92 | AK36: 9.72 | AL36: 89.32 | AM36: =(AK36/100)*(AH36) -> 561.816 | AN36: =(AL36/100)*(AH36) -> 5162.696 | AO36: 10.399033 | AP36: 9.8142165 | AR36: =AP36/$AQ$4 -> 0.91018649 | AS36: 1.47 | AT36: 3.76 | AU36: 4.29 | AV36: 18.15 | AW36: 81.03 | AX36: 18.52 | AY36: 80.32 | AZ36: 18.30006 | BA36: 18.737353 | BB36: 88236 | BC36: 952 | BD36: 92568 | BE36: 200 | BF36: 4042 | BG36: 3594 | BH36: 417 | BI36: 22 | BJ36: 5299 | BK36: 4733 | BL36: 515 | BM36: 24 | BN36: 3394 | BO36: 2750 | BP36: 616 | BQ36: 4324 | BR36: 3473 | BS36: 801 | BT36: 23 | BU36: 1793
A37: 34 | B37: SS | C37: TEST | D37: 4 | E37: 45645 | F37: 3 | G37: 0 | H37: 3.39 | I37: 0 | J37: 1 | K37: 0 | L37: 100000 | M37: 7.1 | N37: =(L37)/(M37) -> 14084.507 | O37: 100000 | P37: 6 | Q37: =(O37)/(P37) -> 16666.667 | R37: 100000 | S37: 4.7 | T37: =(R37)/(S37) -> 21276.596 | U37: 4.2718447 | V37: 12463.06 | W37: 12350.9 | X37: 0.2 | Y37: 0.24 | Z37: 0.49 | AA37: 19.417476 | AB37: 8.0536913 | AC37: 11.136364 | AD37: 0.87 | AE37: 1.03 | AF37: 2.98 | AG37: 4.4 | AH37: =(AG37/100)*100000 -> 4400 | AI37: 8.07 | AJ37: 91.67 | AK37: 7.55 | AL37: 92.13 | AM37: =(AK37/100)*(AH37) -> 332.2 | AN37: =(AL37/100)*(AH37) -> 4053.72 | AO37: 8.0910367 | AP37: 7.5742376 | AR37: =AP37/$AQ$4 -> 0.70244718 | AS37: 1.03 | AT37: 2.24 | AU37: 2.35 | AV37: 19.47 | AW37: 80.25 | AX37: 21.05 | AY37: 78.23 | AZ37: 19.524669 | BA37: 21.202659 | BB37: 92550 | BC37: 796 | BF37: 2774 | BG37: 2543 | BH37: 224 | BI37: 9 | BJ37: 4077 | BK37: 3756 | BL37: 308 | BM37: 25 | BN37: 2121 | BO37: 1702 | BP37: 413 | BQ37: 2361 | BR37: 1847 | BS37: 497 | BT37: 51 | BU37: 1503

Sheet ivSCAs - LM staging data
A1: Parasite development by Light Microscopy (staging) - from sheet 'ivSCAs - Parasite cultures - LM data'
A2: Experiment | B2: Exp1 | C2: Exp1 | D2: Exp1 | E2: Exp1 | F2: Exp2 | G2: Exp2 | H2: Exp2 | I2: Exp2
A3: ID | B3: 1 | C3: 2 | D3: 3 | E3: 4 | F3: 12 | G3: 13 | H3: 10 | I3: 11
A4: Sample type | B4: CTRL FRESH | C4: TEST | D4: TEST | E4: TEST | F4: TEST | G4: TEST | H4: TEST | I4: TEST
A5: Sample sizes (n) | B5: 1 | C5: 2 | E5: 1 | F5: 2 | H5: 2
A6: HBB Genotype | B6: AA | C6: AS | D6: AS | E6: AC | F6: SS | G6: SS | H6: SC | I6: SC
A7: 35-40 hpi (Generation 0)
A8: iRBCs_Gen0_35to40hpi | B8: 1.35 | C8: 2.44 | D8: 2.1 | E8: 1.93 | F8: 0.59 | G8: 0.68 | H8: 1.13 | I8: 1.84
